Workbook

Sheet Huong_Dan
A1: BỘ TEST CASE – WEBSITE SPORTS-K
A2: Kiểm thử và đánh giá chất lượng website thương mại điện tử đồ thể thao Sports-K (React + JSON Server) bằng Selenium, Postman và SonarQube
A4: Cách dùng | B4: Mỗi sheet TC_* là một module. Chạy từng test case, điền 'Kết quả thực tế' và chọn 'Trạng thái'. Nếu Fail: ghi Bug ID vào cột cuối và tạo dòng mới ở sheet Bug_Report. Sheet Tong_Hop tự tính số liệu.
A5: Ô cần điền (màu vàng) | B5: Các cột 'Kết quả thực tế', 'Trạng thái', 'Ghi chú / Bug ID' (và 'Bằng chứng' ở Bug_Report). Các ô khác đã được điền sẵn.
A6: Trạng thái | B6: Not Run (chưa chạy) · Pass · Fail · Blocked (bị chặn, không chạy được). Mặc định là Not Run.
A7: Mức độ nếu lỗi | B7: Mức độ dự kiến nếu test case Fail: Critical / Major / Minor / Trivial (định nghĩa ở sheet Test_Plan). Có thể sửa sau khi xác nhận lỗi.
A8: Cột Công cụ | B8: Selenium = nên tự động hóa; Manual = test thủ công (hoặc có bên thứ ba như Razorpay); Postman = chạy trong Postman collection.
A9: Sheet Bug_Report | B9: Đã điền sẵn các lỗi NGHI VẤN do đọc mã nguồn (Trạng thái = 'Nghi vấn - cần xác minh'). Chỉ chuyển thành 'Đã xác nhận' sau khi tái hiện được; nếu không tái hiện được thì đổi thành 'Không phải lỗi'.
A10: Cột 'Ghi chú / Bug ID' | B10: Với test case có liên quan tới lỗi nghi vấn, cột này đã gợi ý sẵn BUG-xx.
A11: Lưu ý trước khi test | B11: 1) Sao chép mock-server/db.json thành db.backup.json trước khi test Admin, đăng ký và API (các thao tác này ghi vào db.json). 2) Email đăng ký phải khác nhau mỗi lần chạy (thêm timestamp). 3) Razorpay cần Internet; key test trong code có thể đã hết hiệu lực. 4) Dùng bản ghi test cho POST/PATCH/DELETE ở API.
A12: Dữ liệu mẫu | B12: Tài khoản: test@example.com / 123456. Mã giảm giá: family5, family10, family15, family20, family25, family30 (viết thường). Mock API: http://localhost:3001; Web: http://localhost:3000.
A14: Ví dụ một dòng đã điền
A15: Trường | B15: Ví dụ
A16: ID | B16: REG-09
A17: Mô tả | B17: Mật khẩu thiếu chữ hoa
A18: Dữ liệu test | B18: Password: abc#1234
A19: Kết quả mong đợi | B19: Báo lỗi 'at least one upper case'; không cho đăng ký
A20: Kết quả thực tế (ô vàng) | B20: Đăng ký thành công, chuyển sang /login
A21: Trạng thái (ô vàng) | B21: Fail
A22: Ghi chú / Bug ID (ô vàng) | B22: BUG-01 – ảnh chụp: evidence/REG-09.png

Sheet Test_Plan
A1: KẾ HOẠCH KIỂM THỬ (TEST PLAN)
A3: Hệ thống kiểm thử | B3: Sports-K – website thương mại điện tử bán giày và quần áo thể thao (nam/nữ).
A4: Kiến trúc | B4: Frontend: React 18, Redux, Chakra UI, React Router (cổng 3000). Backend giả lập: JSON Server (Node.js, cổng 3001) với các endpoint tự viết /auth/signup, /auth/login, /auth/:email, /allproducts. Thanh toán: Razorpay chế độ test.
A5: Mục tiêu | B5: Phát hiện lỗi chức năng, giao diện, API và mã nguồn; đánh giá chất lượng và độ ổn định; đề xuất cải thiện.
A6: Phạm vi (trong) | B6: Đăng ký; Đăng nhập/đăng xuất/phân quyền route; Danh sách, lọc, sắp xếp sản phẩm; Chi tiết sản phẩm; Giỏ hàng; Wishlist; Mã giảm giá; Checkout và thanh toán (đến Razorpay sandbox); Trang quản trị sản phẩm; Giao diện (responsive, dark mode, trình duyệt); API (Postman); Phân tích mã nguồn (SonarQube).
A7: Ngoài phạm vi | B7: Thanh toán thật; kiểm thử tải lớn; kiểm thử xâm nhập chuyên sâu; SEO; hạ tầng triển khai.
A8: Môi trường (điền) | B8: Hệ điều hành: ........; Node.js: ........; Chrome: ........; Firefox: ........; Edge: ........; Selenium: ........; Postman: ........; SonarQube: Community Build v26.10 (Docker 29.9.1, scanner @sonar/scan)
A9: Công cụ | B9: Selenium WebDriver (kiểm thử giao diện tự động) · Postman/Newman (API) · SonarQube + sonar-scanner (mã nguồn) · Jest + React Testing Library (unit test, tạo coverage cho SonarQube) · Lighthouse (hiệu năng).
A10: Chiến lược | B10: 1) Khám phá thủ công và xác minh lỗi nghi vấn. 2) Thực thi test case thủ công. 3) Tự động hóa các luồng chính bằng Selenium và API bằng Postman. 4) Quét SonarQube và viết unit test. 5) Tổng hợp lỗi và báo cáo.
A11: Tiêu chí bắt đầu | B11: Cả hai máy chủ (3000, 3001) chạy được; đã sao lưu db.json; có tài khoản và dữ liệu test.
A12: Tiêu chí kết thúc | B12: 100% test case được thực thi; không còn lỗi Critical chưa được ghi nhận/phân tích; tỷ lệ Pass và Quality Gate SonarQube được báo cáo kèm phân tích nguyên nhân.
A13: Mức độ lỗi | B13: Critical: lỗ hổng bảo mật nghiêm trọng, mất dữ liệu, chức năng cốt lõi không dùng được. Major: chức năng chính sai hoặc thiếu nhưng có cách khắc phục. Minor: lỗi nhỏ, ảnh hưởng ít tới người dùng. Trivial: lỗi thẩm mỹ, không ảnh hưởng chức năng.
A14: Rủi ro | B14: Key Razorpay test có thể hết hiệu lực; phụ thuộc Internet; test Admin/API làm thay đổi db.json; backend là mock server nên một số lỗi bảo mật xuất phát từ thiết kế giả lập (cần nêu rõ trong báo cáo).

Sheet Tong_Hop
A1: TỔNG HỢP KẾT QUẢ KIỂM THỬ
A3: Module | B3: Tổng số TC | C3: Pass | D3: Fail | E3: Blocked | F3: Not Run | G3: % đã thực hiện | H3: % Pass (trên tổng)
A4: Đăng ký | B4: =COUNTA(TC_DangKy!A2:A500) -> 14 | C4: =COUNTIF(TC_DangKy!H2:H500,"Pass") -> 13 | D4: =COUNTIF(TC_DangKy!H2:H500,"Fail") -> 1 | E4: =COUNTIF(TC_DangKy!H2:H500,"Blocked") -> 0 | F4: =COUNTIF(TC_DangKy!H2:H500,"Not Run") -> 0 | G4: =IFERROR((C4+D4+E4)/B4,0) -> 1 | H4: =IFERROR(C4/B4,0) -> 0.92857143
A5: Đăng nhập | B5: =COUNTA(TC_DangNhap!A2:A500) -> 12 | C5: =COUNTIF(TC_DangNhap!H2:H500,"Pass") -> 9 | D5: =COUNTIF(TC_DangNhap!H2:H500,"Fail") -> 1 | E5: =COUNTIF(TC_DangNhap!H2:H500,"Blocked") -> 0 | F5: =COUNTIF(TC_DangNhap!H2:H500,"Not Run") -> 2 | G5: =IFERROR((C5+D5+E5)/B5,0) -> 0.83333333 | H5: =IFERROR(C5/B5,0) -> 0.75
A6: Lọc / Sắp xếp | B6: =COUNTA(TC_LocSapXep!A2:A500) -> 15 | C6: =COUNTIF(TC_LocSapXep!H2:H500,"Pass") -> 10 | D6: =COUNTIF(TC_LocSapXep!H2:H500,"Fail") -> 1 | E6: =COUNTIF(TC_LocSapXep!H2:H500,"Blocked") -> 1 | F6: =COUNTIF(TC_LocSapXep!H2:H500,"Not Run") -> 3 | G6: =IFERROR((C6+D6+E6)/B6,0) -> 0.8 | H6: =IFERROR(C6/B6,0) -> 0.66666667
A7: Chi tiết sản phẩm | B7: =COUNTA(TC_ChiTiet!A2:A500) -> 8 | C7: =COUNTIF(TC_ChiTiet!H2:H500,"Pass") -> 6 | D7: =COUNTIF(TC_ChiTiet!H2:H500,"Fail") -> 0 | E7: =COUNTIF(TC_ChiTiet!H2:H500,"Blocked") -> 0 | F7: =COUNTIF(TC_ChiTiet!H2:H500,"Not Run") -> 2 | G7: =IFERROR((C7+D7+E7)/B7,0) -> 0.75 | H7: =IFERROR(C7/B7,0) -> 0.75
A8: Giỏ hàng | B8: =COUNTA(TC_GioHang!A2:A500) -> 12 | C8: =COUNTIF(TC_GioHang!H2:H500,"Pass") -> 10 | D8: =COUNTIF(TC_GioHang!H2:H500,"Fail") -> 1 | E8: =COUNTIF(TC_GioHang!H2:H500,"Blocked") -> 0 | F8: =COUNTIF(TC_GioHang!H2:H500,"Not Run") -> 1 | G8: =IFERROR((C8+D8+E8)/B8,0) -> 0.91666667 | H8: =IFERROR(C8/B8,0) -> 0.83333333
A9: Wishlist | B9: =COUNTA(TC_Wishlist!A2:A500) -> 6 | C9: =COUNTIF(TC_Wishlist!H2:H500,"Pass") -> 2 | D9: =COUNTIF(TC_Wishlist!H2:H500,"Fail") -> 1 | E9: =COUNTIF(TC_Wishlist!H2:H500,"Blocked") -> 0 | F9: =COUNTIF(TC_Wishlist!H2:H500,"Not Run") -> 3 | G9: =IFERROR((C9+D9+E9)/B9,0) -> 0.5 | H9: =IFERROR(C9/B9,0) -> 0.33333333
A10: Mã giảm giá | B10: =COUNTA(TC_MaGiamGia!A2:A500) -> 9 | C10: =COUNTIF(TC_MaGiamGia!H2:H500,"Pass") -> 3 | D10: =COUNTIF(TC_MaGiamGia!H2:H500,"Fail") -> 3 | E10: =COUNTIF(TC_MaGiamGia!H2:H500,"Blocked") -> 0 | F10: =COUNTIF(TC_MaGiamGia!H2:H500,"Not Run") -> 3 | G10: =IFERROR((C10+D10+E10)/B10,0) -> 0.66666667 | H10: =IFERROR(C10/B10,0) -> 0.33333333
A11: Checkout / Thanh toán | B11: =COUNTA(TC_Checkout!A2:A500) -> 18 | C11: =COUNTIF(TC_Checkout!H2:H500,"Pass") -> 6 | D11: =COUNTIF(TC_Checkout!H2:H500,"Fail") -> 0 | E11: =COUNTIF(TC_Checkout!H2:H500,"Blocked") -> 0 | F11: =COUNTIF(TC_Checkout!H2:H500,"Not Run") -> 12 | G11: =IFERROR((C11+D11+E11)/B11,0) -> 0.33333333 | H11: =IFERROR(C11/B11,0) -> 0.33333333
A12: Quản trị | B12: =COUNTA(TC_Admin!A2:A500) -> 10 | C12: =COUNTIF(TC_Admin!H2:H500,"Pass") -> 3 | D12: =COUNTIF(TC_Admin!H2:H500,"Fail") -> 1 | E12: =COUNTIF(TC_Admin!H2:H500,"Blocked") -> 0 | F12: =COUNTIF(TC_Admin!H2:H500,"Not Run") -> 6 | G12: =IFERROR((C12+D12+E12)/B12,0) -> 0.4 | H12: =IFERROR(C12/B12,0) -> 0.3
A13: Giao diện | B13: =COUNTA(TC_GiaoDien!A2:A500) -> 11 | C13: =COUNTIF(TC_GiaoDien!H2:H500,"Pass") -> 4 | D13: =COUNTIF(TC_GiaoDien!H2:H500,"Fail") -> 2 | E13: =COUNTIF(TC_GiaoDien!H2:H500,"Blocked") -> 0 | F13: =COUNTIF(TC_GiaoDien!H2:H500,"Not Run") -> 5 | G13: =IFERROR((C13+D13+E13)/B13,0) -> 0.54545455 | H13: =IFERROR(C13/B13,0) -> 0.36363636
A14: API (Postman) | B14: =COUNTA(TC_API!A2:A500) -> 30 | C14: =COUNTIF(TC_API!J2:J500,"Pass") -> 23 | D14: =COUNTIF(TC_API!J2:J500,"Fail") -> 7 | E14: =COUNTIF(TC_API!J2:J500,"Blocked") -> 0 | F14: =COUNTIF(TC_API!J2:J500,"Not Run") -> 0 | G14: =IFERROR((C14+D14+E14)/B14,0) -> 1 | H14: =IFERROR(C14/B14,0) -> 0.76666667
A15: TỔNG | B15: =SUM(B4:B14) -> 145 | C15: =SUM(C4:C14) -> 89 | D15: =SUM(D4:D14) -> 18 | E15: =SUM(E4:E14) -> 1 | F15: =SUM(F4:F14) -> 37 | G15: =IFERROR((C15+D15+E15)/B15,0) -> 0.74482759 | H15: =IFERROR(C15/B15,0) -> 0.6137931
A17: THỐNG KÊ LỖI (Bug_Report)
A18: Mức độ | B18: Tổng | C18: Nghi vấn | D18: Đã xác nhận | E18: Đã sửa
A19: Critical | B19: =COUNTIF(Bug_Report!H2:H500,"Critical") -> 4 | C19: =COUNTIFS(Bug_Report!H2:H500,"Critical",Bug_Report!J2:J500,"Nghi vấn - cần xác minh") -> 0 | D19: =COUNTIFS(Bug_Report!H2:H500,"Critical",Bug_Report!J2:J500,"Đã xác nhận") -> 4 | E19: =COUNTIFS(Bug_Report!H2:H500,"Critical",Bug_Report!J2:J500,"Đã sửa") -> 0
A20: Major | B20: =COUNTIF(Bug_Report!H2:H500,"Major") -> 8 | C20: =COUNTIFS(Bug_Report!H2:H500,"Major",Bug_Report!J2:J500,"Nghi vấn - cần xác minh") -> 5 | D20: =COUNTIFS(Bug_Report!H2:H500,"Major",Bug_Report!J2:J500,"Đã xác nhận") -> 3 | E20: =COUNTIFS(Bug_Report!H2:H500,"Major",Bug_Report!J2:J500,"Đã sửa") -> 0
A21: Minor | B21: =COUNTIF(Bug_Report!H2:H500,"Minor") -> 14 | C21: =COUNTIFS(Bug_Report!H2:H500,"Minor",Bug_Report!J2:J500,"Nghi vấn - cần xác minh") -> 5 | D21: =COUNTIFS(Bug_Report!H2:H500,"Minor",Bug_Report!J2:J500,"Đã xác nhận") -> 8 | E21: =COUNTIFS(Bug_Report!H2:H500,"Minor",Bug_Report!J2:J500,"Đã sửa") -> 0
A22: Trivial | B22: =COUNTIF(Bug_Report!H2:H500,"Trivial") -> 1 | C22: =COUNTIFS(Bug_Report!H2:H500,"Trivial",Bug_Report!J2:J500,"Nghi vấn - cần xác minh") -> 0 | D22: =COUNTIFS(Bug_Report!H2:H500,"Trivial",Bug_Report!J2:J500,"Đã xác nhận") -> 1 | E22: =COUNTIFS(Bug_Report!H2:H500,"Trivial",Bug_Report!J2:J500,"Đã sửa") -> 0
A23: TỔNG | B23: =SUM(B19:B22) -> 27 | C23: =SUM(C19:C22) -> 10 | D23: =SUM(D19:D22) -> 16 | E23: =SUM(E19:E22) -> 0
A25: Ghi chú: các số liệu trên là công thức, tự cập nhật khi bạn đổi Trạng thái ở các sheet TC_* và Bug_Report.

Sheet TC_DangKy
A1: ID | B1: Mô tả | C1: Điều kiện tiên quyết | D1: Các bước thực hiện | E1: Dữ liệu test | F1: Kết quả mong đợi | G1: Kết quả thực tế | H1: Trạng thái | I1: Mức độ nếu lỗi | J1: Công cụ | K1: Ghi chú / Bug ID
A2: REG-01 | B2: Đăng ký thành công với dữ liệu hợp lệ | C2: Đang ở /register; email chưa tồn tại | D2: 1. Mở /register 2. Nhập đủ 5 trường 3. Bấm Sign up | E2: Name: Nguyen Username: nguyen01 Email: nguyen01@example.com Password: Abc#1234 Mobile: 0912345678 | F2: Toast 'Registered Successful'; chuyển sang /login; POST /auth/signup trả 201; db.json có user mới | G2: Đúng như mong đợi | H2: Pass | I2: Critical | J2: Selenium
A3: REG-02 | B3: Để trống tất cả các trường | C3: Đang ở /register | D3: 1. Không nhập gì 2. Bấm Sign up | E3: Tất cả để trống | F3: Toast lỗi 'Please fill all the details'; không gọi API | G3: Đúng như mong đợi | H3: Pass | I3: Major | J3: Selenium
A4: REG-03 | B4: Để trống lần lượt từng trường bắt buộc | C4: Đang ở /register | D4: 1. Nhập hợp lệ 4 trường, bỏ trống 1 trường 2. Bấm Sign up 3. Lặp lại cho từng trường | E4: Lần lượt bỏ trống: Name, Username, Email, Password, Mobile | F4: Mỗi lần đều báo 'Please fill all the details' | G4: Đúng như mong đợi | H4: Pass | I4: Major | J4: Selenium
A5: REG-04 | B5: Tên không viết hoa chữ cái đầu | C5: Đang ở /register | D5: 1. Nhập Name viết thường 2. Các trường khác hợp lệ 3. Bấm Sign up | E5: Name: nguyen | F5: Toast lỗi: First latter should be Capital in "nguyen" | G5: Đúng như mong đợi | H5: Pass | I5: Minor | J5: Selenium
A6: REG-05 | B6: Email thiếu ký tự @ | C6: Đang ở /register | D6: 1. Nhập email sai định dạng 2. Bấm Sign up | E6: Email: nguyen01example.com | F6: Toast 'Please provide a valid email id' | G6: Đúng như mong đợi | H6: Pass | I6: Major | J6: Selenium
A7: REG-06 | B7: Email thiếu phần tên miền (dấu chấm) | C7: Đang ở /register | D7: 1. Nhập email sai 2. Bấm Sign up | E7: Email: nguyen01@example | F7: Toast 'Please provide a valid email id' | G7: Đúng như mong đợi | H7: Pass | I7: Major | J7: Selenium
A8: REG-07 | B8: Mật khẩu ngắn hơn 6 ký tự | C8: Đang ở /register | D8: 1. Nhập mật khẩu ngắn 2. Bấm Sign up | E8: Password: Ab#1 | F8: Toast 'Password must contain these things:' kèm 'at least 6 characters' | G8: Đúng như mong đợi | H8: Pass | I8: Major | J8: Selenium
A9: REG-08 | B9: Mật khẩu dài hơn 16 ký tự | C9: Đang ở /register | D9: 1. Nhập mật khẩu 17 ký tự 2. Bấm Sign up | E9: Password: Abcdefgh#12345678 (17 ký tự) | F9: Toast báo 'not more than 16 characters' | G9: Đúng như mong đợi | H9: Pass | I9: Major | J9: Selenium
A10: REG-09 | B10: Mật khẩu thiếu chữ hoa | C10: Đang ở /register | D10: 1. Nhập mật khẩu chỉ có chữ thường, số, ký tự đặc biệt 2. Bấm Sign up | E10: Password: abc#1234 | F10: Báo lỗi 'at least one upper case'; không cho đăng ký | G10: AssertionError: Kỳ vọng báo lỗi chữ hoa (nghi vấn BUG-01) | H10: Fail | I10: Major | J10: Selenium | K10: Bug: BUG-01
A11: REG-10 | B11: Mật khẩu thiếu chữ số / thiếu ký tự đặc biệt | C11: Đang ở /register | D11: 1. Nhập từng mật khẩu bên dưới 2. Bấm Sign up | E11: Abcdef#g (thiếu số) Abcd1234 (thiếu ký tự đặc biệt) | F11: Báo 'at least one number' / 'at least one special character(! @ # $ % ^ & *)' | G11: Đúng như mong đợi | H11: Pass | I11: Major | J11: Selenium
A12: REG-11 | B12: Số điện thoại không đủ 10 chữ số | C12: Đang ở /register | D12: 1. Nhập SĐT 9 chữ số 2. Bấm Sign up | E12: Mobile: 091234567 | F12: Toast 'Please provide 10 digit valid mobile number' | G12: Đúng như mong đợi | H12: Pass | I12: Major | J12: Selenium
A13: REG-12 | B13: Số điện thoại chứa chữ cái (đủ 10 ký tự) | C13: Đang ở /register | D13: 1. Nhập SĐT có chữ 2. Bấm Sign up | E13: Mobile: 09123abcde | F13: Không cho đăng ký (SĐT chỉ gồm chữ số) | G13: Đúng như mong đợi | H13: Pass | I13: Minor | J13: Selenium | K13: Bug: BUG-14 (không tái hiện qua UI)
A14: REG-13 | B14: Đăng ký bằng email đã tồn tại | C14: Tài khoản test@example.com đã có | D14: 1. Nhập email đã tồn tại, các trường khác hợp lệ 2. Bấm Sign up | E14: Email: test@example.com | F14: Toast 'User already exists' (API 409); ở lại /register | G14: Đúng như mong đợi | H14: Pass | I14: Major | J14: Selenium
A15: REG-14 | B15: Nút hiện/ẩn mật khẩu | C15: Đang ở /register | D15: 1. Nhập mật khẩu 2. Bấm biểu tượng mắt 2 lần | E15: Password: Abc#1234 | F15: Lần 1 hiện dạng chữ, lần 2 ẩn lại | G15: Đúng như mong đợi | H15: Pass | I15: Trivial | J15: Selenium

Sheet TC_DangNhap
A1: ID | B1: Mô tả | C1: Điều kiện tiên quyết | D1: Các bước thực hiện | E1: Dữ liệu test | F1: Kết quả mong đợi | G1: Kết quả thực tế | H1: Trạng thái | I1: Mức độ nếu lỗi | J1: Công cụ | K1: Ghi chú / Bug ID
A2: LOG-01 | B2: Đăng nhập thành công | C2: Tài khoản mẫu tồn tại | D2: 1. Mở /login 2. Nhập Email, Password 3. Bấm Sign in | E2: test@example.com / 123456 | F2: Toast 'Login Success'; chuyển về '/'; localStorage có 'token' và 'userInfo'; Navbar hiển thị thông tin người dùng | G2: Đúng như mong đợi | H2: Pass | I2: Critical | J2: Selenium
A3: LOG-02 | B3: Đăng nhập sai mật khẩu | C3: Đang ở /login | D3: 1. Nhập email đúng, mật khẩu sai 2. Bấm Sign in 3. Đếm số toast hiển thị | E3: test@example.com / Sai#1234 | F3: Toast 'Wrong email or password' (API 401); ở lại /login; không lưu token; chỉ 1 toast | G3: Đúng như mong đợi | H3: Pass | I3: Major | J3: Selenium | K3: Bug: BUG-13 (không tái hiện)
A4: LOG-03 | B4: Đăng nhập email không tồn tại | C4: Đang ở /login | D4: 1. Nhập email chưa đăng ký 2. Bấm Sign in | E4: khongco@example.com / 123456 | F4: Toast 'Wrong email or password'; ở lại /login | G4: Đúng như mong đợi | H4: Pass | I4: Major | J4: Selenium
A5: LOG-04 | B5: Để trống Email hoặc Password | C5: Đang ở /login | D5: 1. Bỏ trống một trường 2. Bấm Sign in | E5: Email trống hoặc Password trống | F5: Hiển thị thông báo yêu cầu nhập đủ thông tin; không gọi API | G5: AssertionError: Không có thông báo khi để trống (nghi vấn BUG-12) | H5: Fail | I5: Minor | J5: Selenium | K5: Bug: BUG-12
A6: LOG-05 | B6: Nút hiện/ẩn mật khẩu | C6: Đang ở /login | D6: 1. Nhập mật khẩu 2. Bấm biểu tượng mắt 2 lần | E6: Password: 123456 | F6: Lần 1 hiện chữ, lần 2 ẩn lại | G6: Đúng như mong đợi | H6: Pass | I6: Trivial | J6: Selenium
A7: LOG-06 | B7: Truy cập /checkout khi chưa đăng nhập, quay lại sau khi đăng nhập | C7: Chưa đăng nhập (xóa localStorage) | D7: 1. Mở trực tiếp /checkout 2. Quan sát 3. Đăng nhập hợp lệ | E7: test@example.com / 123456 | F7: Bị chuyển sang /login; sau khi đăng nhập quay lại /checkout | G7: Đúng như mong đợi | H7: Pass | I7: Major | J7: Selenium
A8: LOG-07 | B8: Truy cập /wishlist khi chưa đăng nhập | C8: Chưa đăng nhập | D8: 1. Mở trực tiếp /wishlist | E8: — | F8: Bị chuyển sang /login | G8: Đúng như mong đợi | H8: Pass | I8: Major | J8: Selenium
A9: LOG-08 | B9: Giữ phiên đăng nhập sau khi tải lại trang (F5) | C9: Đã đăng nhập | D9: 1. Nhấn F5 2. Mở /wishlist | E9: — | F9: Vẫn đăng nhập; không bị chuyển về /login | G9: Đúng như mong đợi | H9: Pass | I9: Major | J9: Selenium
A10: LOG-09 | B10: Đăng xuất | C10: Đã đăng nhập | D10: 1. Mở menu tài khoản trên Navbar 2. Chọn Logout 3. Mở /wishlist | E10: — | F10: Xóa 'token' và 'userInfo' trong localStorage; /wishlist bị chuyển về /login | G10: Đúng như mong đợi | H10: Pass | I10: Major | J10: Selenium
A11: LOG-10 | B11: Đăng nhập bằng tài khoản admin hardcode trong code | C11: Đang ở /login | D11: 1. Nhập thông tin admin có trong Login.jsx 2. Bấm Sign in | E11: nareshmewada014@gmail.com / naresh#111* | F11: Tài khoản không có trong db.json → đăng nhập thất bại, không vào được /admin | H11: Not Run | I11: Critical | J11: Manual | K11: Gợi ý: liên quan BUG-08 (nghi vấn)
A12: LOG-11 | B12: Chuỗi tấn công SQL injection cơ bản | C12: Đang ở /login | D12: 1. Nhập chuỗi bên dưới vào cả 2 trường 2. Bấm Sign in | E12: Email: ' OR '1'='1 Password: ' OR '1'='1 | F12: Đăng nhập thất bại (401); không lỗi 500; không vào được hệ thống | G12: Đúng như mong đợi | H12: Pass | I12: Major | J12: Selenium
A13: LOG-12 | B13: Remember me và Forgot password | C13: Đang ở /login | D13: 1. Tick 'Remember me' 2. Bấm 'Forgot password?' | E13: — | F13: Chức năng hoạt động, hoặc được ẩn nếu chưa hỗ trợ | H13: Not Run | I13: Minor | J13: Manual

Sheet TC_LocSapXep
A1: ID | B1: Mô tả | C1: Điều kiện tiên quyết | D1: Các bước thực hiện | E1: Dữ liệu test | F1: Kết quả mong đợi | G1: Kết quả thực tế | H1: Trạng thái | I1: Mức độ nếu lỗi | J1: Công cụ | K1: Ghi chú / Bug ID
A2: FIL-01 | B2: Hiển thị toàn bộ sản phẩm khi chưa lọc | C2: mock-server đang chạy | D2: 1. Mở /allproducts 2. Đếm số thẻ sản phẩm | E2: — | F2: Hiển thị 28 sản phẩm; mỗi thẻ có ảnh, tên, giá | G2: Đúng như mong đợi | H2: Pass | I2: Major | J2: Selenium
A3: FIL-02 | B3: Trang /men chỉ hiển thị sản phẩm nam | C3: — | D3: 1. Mở /men 2. Đếm và kiểm tra giới tính | E3: — | F3: 14 sản phẩm MEN, không lẫn sản phẩm nữ | G3: Đúng như mong đợi | H3: Pass | I3: Major | J3: Selenium
A4: FIL-03 | B4: Trang /women chỉ hiển thị sản phẩm nữ | C4: — | D4: 1. Mở /women 2. Đếm và kiểm tra giới tính | E4: — | F4: 14 sản phẩm WOMEN, không lẫn sản phẩm nam | G4: Đúng như mong đợi | H4: Pass | I4: Major | J4: Selenium
A5: FIL-04 | B5: Trang /shoes chỉ hiển thị giày | C5: — | D5: 1. Mở /shoes 2. Đếm và kiểm tra loại | E5: — | F5: 16 sản phẩm category=shoes, không có quần áo | G5: Đúng như mong đợi | H5: Pass | I5: Major | J5: Selenium
A6: FIL-05 | B6: Lọc theo loại (Category) | C6: Đang ở /allproducts | D6: 1. Tick 'Clothes' → ghi số lượng 2. Bỏ, tick 'Shoes' 3. Tick cả hai | E6: Clothes / Shoes / cả hai | F6: Clothes: 12; Shoes: 16; cả hai: 28 | G6: Đúng như mong đợi | H6: Pass | I6: Major | J6: Selenium
A7: FIL-06 | B7: Lọc theo một màu | C7: Đang ở /allproducts | D7: 1. Tick màu Black 2. So sánh với GET /allproducts?colortype=black | E7: Color: Black | F7: 7 sản phẩm màu black; số lượng khớp API | G7: Đúng như mong đợi | H7: Pass | I7: Major | J7: Selenium
A8: FIL-07 | B8: Lọc nhiều màu (Red + Blue) | C8: Đang ở /allproducts | D8: 1. Tick Red và Blue | E8: Color: Red, Blue | F8: 14 sản phẩm (hợp của 2 màu, logic OR) | G8: Đúng như mong đợi | H8: Pass | I8: Major | J8: Selenium
A9: FIL-08 | B9: Kết hợp nhiều bộ lọc | C9: Đang ở /allproducts | D9: 1. Tick Shoes + MEN → ghi số lượng 2. Đổi sang Shoes + WOMEN + White | E9: Shoes + MEN Shoes + WOMEN + White | F9: Shoes + MEN: 8 sản phẩm; Shoes + WOMEN + White: 2 sản phẩm (giao của các điều kiện) | G9: Đúng như mong đợi | H9: Pass | I9: Major | J9: Selenium
A10: FIL-09 | B10: Lọc theo size Small | C10: Đang ở /allproducts | D10: 1. Tick Size 'small' | E10: Size: small | F10: 12 sản phẩm là quần áo có size small | G10: Mục lọc Size không có trên giao diện (khối mã bị comment) | H10: Fail | I10: Major | J10: Selenium | K10: Bug: BUG-19
A11: FIL-10 | B11: Sắp xếp theo đánh giá (rating) | C11: Đang ở /allproducts | D11: 1. Chọn sắp xếp ASC → ghi thứ tự rating 2. Chọn DESC → ghi thứ tự rating | E11: ASC, DESC | F11: ASC: rating tăng dần; DESC: giảm dần; số lượng sản phẩm không đổi | G11: Đúng như mong đợi | H11: Pass | I11: Major | J11: Selenium
A12: FIL-11 | B12: Bộ lọc size có áp dụng cho giày (6–10) không | C12: Đang ở /shoes | D12: 1. Quan sát mục Size trong bộ lọc | E12: Size giày: 6, 7, 8, 9, 10 | F12: Có tùy chọn lọc size giày (hoặc ghi nhận rõ là không hỗ trợ) | H12: Not Run | I12: Minor | J12: Manual | K12: Gợi ý: liên quan BUG-19 (nghi vấn)
A13: FIL-12 | B13: Bộ lọc cho kết quả rỗng | C13: Đang ở /allproducts | D13: 1. Tick Shoes 2. Tick Size 'small' | E13: Shoes + small | F13: Hiển thị trạng thái rỗng thân thiện; không lỗi hoặc trang trắng | G13: Dữ liệu db.json có đủ mọi tổ hợp Category×Gender×Color -> không tạo được kết quả rỗng qua UI; test thủ công bằng URL | H13: Blocked | I13: Minor | J13: Selenium
A14: FIL-13 | B14: Giữ bộ lọc theo URL và khi tải lại trang | C14: Đang ở /allproducts | D14: 1. Tick Shoes + Red 2. Copy URL, nhấn F5 3. Mở URL ở tab mới | E14: Shoes + Red | F14: Checkbox vẫn được chọn; kết quả giống nhau ở cả 3 trường hợp | G14: Đúng như mong đợi | H14: Pass | I14: Minor | J14: Selenium
A15: FIL-14 | B15: Lọc trên trang /shoes khi chọn thêm Clothes | C15: Đang ở /shoes | D15: 1. Tick 'Clothes' trong bộ lọc Category | E15: Category: Clothes | F15: Hành vi nhất quán với tên trang (ghi nhận kết quả thực tế) | H15: Not Run | I15: Minor | J15: Manual
A16: FIL-15 | B16: Tìm kiếm sản phẩm theo từ khóa | C16: — | D16: 1. Tìm ô/biểu tượng tìm kiếm trên Navbar 2. Nhập 'Air Runner' | E16: Từ khóa: Air Runner | F16: Có chức năng tìm kiếm và trả về đúng sản phẩm | H16: Not Run | I16: Minor | J16: Manual | K16: Gợi ý: liên quan BUG-16 (nghi vấn)

Sheet TC_ChiTiet
A1: ID | B1: Mô tả | C1: Điều kiện tiên quyết | D1: Các bước thực hiện | E1: Dữ liệu test | F1: Kết quả mong đợi | G1: Kết quả thực tế | H1: Trạng thái | I1: Mức độ nếu lỗi | J1: Công cụ | K1: Ghi chú / Bug ID
A2: DET-01 | B2: Hiển thị thông tin chi tiết sản phẩm | C2: — | D2: 1. Từ /allproducts bấm sản phẩm id=1 | E2: Sản phẩm: Air Runner M | F2: URL /description/1; tên 'Air Runner M'; giá gốc gạch ngang 712.000 ₫; giá bán 562.000 ₫; màu red; size 6, 7, 8, 9, 10 | G2: Đúng như mong đợi | H2: Pass | I2: Major | J2: Selenium
A3: DET-02 | B3: Nút thêm vào giỏ khi chưa chọn size | C3: Đang ở trang chi tiết | D3: 1. Không chọn size 2. Quan sát nút thêm vào giỏ | E3: — | F3: Nút bị vô hiệu và hiển thị 'Please Select A Size' | G3: Đúng như mong đợi | H3: Pass | I3: Major | J3: Selenium
A4: DET-03 | B4: Chọn size và thêm vào giỏ | C4: Đang ở trang chi tiết | D4: 1. Chọn một size 2. Bấm 'ADD TO BAG' | E4: Size: 6 | F4: Nút đổi thành 'ADD TO BAG'; toast 'Item added to your bag'; số lượng trên biểu tượng giỏ +1 | G4: Đúng như mong đợi | H4: Pass | I4: Critical | J4: Selenium
A5: DET-04 | B5: Thêm vào danh sách yêu thích | C5: Đang ở trang chi tiết | D5: 1. Bấm 'ADD TO FAVOURITE' | E5: — | F5: Có phản hồi (toast); số lượng wishlist trên Navbar +1 (ghi nhận có yêu cầu đăng nhập hay không) | G5: Đúng như mong đợi | H5: Pass | I5: Major | J5: Selenium
A6: DET-05 | B6: Truy cập sản phẩm không tồn tại | C6: — | D6: 1. Mở /description/9999 | E6: id = 9999 | F6: Thông báo 'không tìm thấy sản phẩm' hoặc chuyển 404; không trang trắng/crash | H6: Not Run | I6: Minor | J6: Manual
A7: DET-06 | B7: Truy cập sản phẩm với id không hợp lệ | C7: — | D7: 1. Mở /description/abc | E7: id = abc | F7: Xử lý lỗi thân thiện; không crash ứng dụng | H7: Not Run | I7: Minor | J7: Manual
A8: DET-07 | B8: Tải ảnh sản phẩm | C8: — | D8: 1. Mở trang chi tiết 2. Kiểm tra từng ảnh | E8: 5 ảnh/sản phẩm từ localhost:3001/photos | F8: Tất cả ảnh tải được, không ảnh vỡ | G8: Đúng như mong đợi | H8: Pass | I8: Minor | J8: Selenium
A9: DET-08 | B9: Quy đổi giá sang VND | C9: — | D9: 1. Mở trang chi tiết của id 1, 2, 3 2. So sánh giá hiển thị với giá trị mong đợi | E9: id 1, 2, 3 | F9: id=1: gốc 712.000 ₫; bán 562.000 ₫ id=2: gốc 824.000 ₫; bán 674.000 ₫ id=3: gốc 936.000 ₫; bán 786.000 ₫ | G9: Đúng như mong đợi | H9: Pass | I9: Major | J9: Selenium

Sheet TC_GioHang
A1: ID | B1: Mô tả | C1: Điều kiện tiên quyết | D1: Các bước thực hiện | E1: Dữ liệu test | F1: Kết quả mong đợi | G1: Kết quả thực tế | H1: Trạng thái | I1: Mức độ nếu lỗi | J1: Công cụ | K1: Ghi chú / Bug ID
A2: CART-01 | B2: Giỏ hàng trống | C2: Chưa thêm sản phẩm | D2: 1. Mở /cart | E2: — | F2: Hiển thị màn hình giỏ trống; không có nút thanh toán | G2: Đúng như mong đợi | H2: Pass | I2: Major | J2: Selenium
A3: CART-02 | B3: Thêm 1 sản phẩm vào giỏ | C3: — | D3: 1. Mở sản phẩm id=1 2. Chọn size, thêm vào giỏ 3. Mở /cart | E3: Air Runner M, size 6 | F3: Có 1 dòng: tên, size, màu, SL=1; 'TOTAL [1 items]'; badge Navbar = 1 | G3: Đúng như mong đợi | H3: Pass | I3: Critical | J3: Selenium
A4: CART-03 | B4: Thêm cùng sản phẩm, cùng size | C4: Giỏ có 1 sản phẩm | D4: 1. Thêm lại cùng sản phẩm và size | E4: Air Runner M, size 6 | F4: Chỉ 1 dòng, SL = 2 | G4: Đúng như mong đợi | H4: Pass | I4: Major | J4: Selenium
A5: CART-04 | B5: Thêm cùng sản phẩm, khác size | C5: Giỏ có 1 sản phẩm | D5: 1. Thêm lại cùng sản phẩm nhưng chọn size khác | E5: Size 6 và 7 | F5: Có 2 dòng riêng cho 2 size | G5: Đúng như mong đợi | H5: Pass | I5: Major | J5: Selenium
A6: CART-05 | B6: Tăng số lượng bằng nút + | C6: Giỏ có 1 dòng SL=1 | D6: 1. Bấm nút + | E6: — | F6: SL tăng 1; tổng tiền cập nhật | G6: Đúng như mong đợi | H6: Pass | I6: Major | J6: Selenium
A7: CART-06 | B7: Giảm số lượng bằng nút − | C7: Giỏ có 1 dòng SL=2 | D7: 1. Bấm nút − | E7: — | F7: SL giảm còn 1; tổng tiền cập nhật | G7: Đúng như mong đợi | H7: Pass | I7: Major | J7: Selenium
A8: CART-07 | B8: Giảm số lượng khi SL = 1 | C8: Giỏ có 1 dòng SL=1 | D8: 1. Bấm nút − | E8: — | F8: Sản phẩm bị xóa khỏi giỏ; nếu giỏ rỗng hiển thị màn hình giỏ trống | G8: Đúng như mong đợi | H8: Pass | I8: Major | J8: Selenium
A9: CART-08 | B9: Tính tổng tiền | C9: Giỏ trống | D9: 1. Thêm 2 × id=1 và 1 × id=2 (size bất kỳ) 2. Mở /cart | E9: 2 × Air Runner M (id=1) + 1 × Court Classic M (id=2) | F9: 'TOTAL [3 items]'; ORIGINAL PRICE 2.248.000 ₫; tổng thanh toán 1.798.000 ₫ | G9: Đúng như mong đợi | H9: Pass | I9: Critical | J9: Selenium
A10: CART-09 | B10: Giữ giỏ hàng sau khi tải lại trang (F5) | C10: Giỏ có sản phẩm | D10: 1. Nhấn F5 ở /cart | E10: — | F10: Giỏ hàng vẫn còn đầy đủ | G10: AssertionError: Giỏ hàng mất sau F5 (nghi vấn BUG-09) | H10: Fail | I10: Major | J10: Selenium | K10: Bug: BUG-09
A11: CART-10 | B11: Badge số lượng trên Navbar | C11: Giỏ có nhiều dòng | D11: 1. So sánh số trên biểu tượng giỏ với tổng SL | E11: 2 × Air Runner M (id=1) + 1 × Court Classic M (id=2) | F11: Badge = 3 (tổng số lượng) | G11: Đúng như mong đợi | H11: Pass | I11: Minor | J11: Selenium
A12: CART-11 | B12: Xem giỏ khi chưa đăng nhập và bấm thanh toán | C12: Chưa đăng nhập, giỏ có sản phẩm | D12: 1. Mở /cart 2. Bấm nút thanh toán | E12: — | F12: Xem được /cart; bấm thanh toán → chuyển /login; đăng nhập xong quay lại /checkout | G12: Đúng như mong đợi | H12: Pass | I12: Major | J12: Selenium
A13: CART-12 | B13: Số lượng rất lớn | C13: Giỏ có 1 dòng | D13: 1. Bấm nút + nhiều lần (≥ 50) | E13: SL ≥ 50 | F13: Có giới hạn hợp lý hoặc giao diện không vỡ; ghi nhận không kiểm tra tồn kho | H13: Not Run | I13: Trivial | J13: Manual

Sheet TC_Wishlist
A1: ID | B1: Mô tả | C1: Điều kiện tiên quyết | D1: Các bước thực hiện | E1: Dữ liệu test | F1: Kết quả mong đợi | G1: Kết quả thực tế | H1: Trạng thái | I1: Mức độ nếu lỗi | J1: Công cụ | K1: Ghi chú / Bug ID
A2: WL-01 | B2: Thêm sản phẩm vào wishlist | C2: Đã đăng nhập | D2: 1. Mở trang chi tiết 2. Bấm 'ADD TO FAVOURITE' 3. Mở /wishlist | E2: Air Runner M | F2: Sản phẩm xuất hiện trong /wishlist | G2: Đúng như mong đợi | H2: Pass | I2: Major | J2: Selenium
A3: WL-02 | B3: Thêm trùng cùng sản phẩm | C3: Wishlist có sản phẩm id=1 | D3: 1. Thêm lại id=1 | E3: Air Runner M | F3: Chỉ có 1 mục, không tạo bản sao | G3: Đúng như mong đợi | H3: Pass | I3: Minor | J3: Selenium
A4: WL-03 | B4: Xóa sản phẩm khỏi wishlist | C4: Wishlist có sản phẩm | D4: 1. Bấm nút X đỏ | E4: — | F4: Sản phẩm biến mất; badge Navbar giảm 1 | H4: Not Run | I4: Major | J4: Selenium
A5: WL-04 | B5: Mở sản phẩm từ wishlist | C5: Wishlist có sản phẩm | D5: 1. Bấm vào ảnh/tên sản phẩm | E5: — | F5: Chuyển tới /description/{id} | H5: Not Run | I5: Minor | J5: Selenium
A6: WL-05 | B6: Badge wishlist trên Navbar | C6: Wishlist có 2 sản phẩm | D6: 1. So sánh badge với số sản phẩm | E6: — | F6: Badge = 2 | H6: Not Run | I6: Minor | J6: Selenium
A7: WL-06 | B7: Giữ wishlist sau khi tải lại trang | C7: Wishlist có sản phẩm | D7: 1. Nhấn F5 ở /wishlist | E7: — | F7: Wishlist vẫn còn | G7: selenium.common.exceptions.TimeoutException: Message: | H7: Fail | I7: Minor | J7: Selenium | K7: Ảnh: results/screenshots/WL-06.png; Bug: BUG-09

Sheet TC_MaGiamGia
A1: ID | B1: Mô tả | C1: Điều kiện tiên quyết | D1: Các bước thực hiện | E1: Dữ liệu test | F1: Kết quả mong đợi | G1: Kết quả thực tế | H1: Trạng thái | I1: Mức độ nếu lỗi | J1: Công cụ | K1: Ghi chú / Bug ID
A2: CPN-01 | B2: Áp từng mã giảm giá hợp lệ | C2: Đã đăng nhập; giỏ: 2 × Air Runner M (id=1) + 1 × Court Classic M (id=2); đang ở /checkout | D2: 1. Nhập mã, bấm nút áp dụng 2. Ghi DISCOUNT và TOTAL 3. Gỡ mã, lặp với mã tiếp theo | E2: family5, family10, family15, family20, family25, family30 | F2: family5: DISCOUNT ≈ 90.000 ₫; TOTAL ≈ 1.708.000 ₫ family10: DISCOUNT ≈ 180.000 ₫; TOTAL ≈ 1.618.000 ₫ family15: DISCOUNT ≈ 269.000 ₫; TOTAL ≈ 1.528.000 ₫ family20: DISCOUNT ≈ 359.000 ₫; TOTAL ≈ 1.438.000 ₫ family25: DISCOUNT ≈ 449.000 ₫; TOTAL ≈ 1.348.000 ₫ family30: DISCOUNT ≈ 539.000 ₫; TOTAL ≈ 1.259.000 ₫ (Giá trị tham chiếu theo công thức trong code; đối chiếu với màn hình) | G2: Đúng như mong đợi | H2: Pass | I2: Critical | J2: Selenium
A3: CPN-02 | B3: Thông báo khi áp mã thành công | C3: Như CPN-01 | D3: 1. Nhập family10, bấm áp dụng | E3: family10 | F3: Toast 'Coupon Applied Successfully' – 'You got 10% Discount'; ô nhập bị khóa | H3: Not Run | I3: Minor | J3: Selenium
A4: CPN-03 | B4: Mã không hợp lệ | C4: Như CPN-01 | D4: 1. Nhập mã sai, bấm áp dụng | E4: abc123 | F4: Hiển thị thông báo mã không hợp lệ; DISCOUNT = 0 | G4: assert (False or False) | H4: Fail | I4: Minor | J4: Selenium | K4: Ảnh: results/screenshots/CPN-03.png; Bug: BUG-25
A5: CPN-04 | B5: Mã viết hoa | C5: Như CPN-01 | D5: 1. Nhập mã viết hoa, bấm áp dụng | E5: FAMILY10 | F5: Mã được chấp nhận (không phân biệt hoa/thường) hoặc báo lỗi rõ ràng | G5: AssertionError: Mã viết hoa không được chấp nhận (code so sánh ===) | H5: Fail | I5: Minor | J5: Selenium | K5: Ảnh: results/screenshots/CPN-04.png; Bug: BUG-26
A6: CPN-05 | B6: Mã có khoảng trắng đầu/cuối | C6: Như CPN-01 | D6: 1. Nhập mã có khoảng trắng, bấm áp dụng | E6: 'family10 ' | F6: Mã được chấp nhận sau khi bỏ khoảng trắng | G6: assert False | H6: Fail | I6: Trivial | J6: Selenium | K6: Ảnh: results/screenshots/CPN-05.png; Bug: BUG-26
A7: CPN-06 | B7: Bấm áp dụng khi chưa nhập mã | C7: Như CPN-01 | D7: 1. Để trống, bấm áp dụng | E7: (trống) | F7: Không áp giảm giá; không lỗi | H7: Not Run | I7: Trivial | J7: Selenium
A8: CPN-07 | B8: Gỡ mã đã áp dụng | C8: Đã áp family10 | D8: 1. Bấm biểu tượng X để gỡ mã | E8: family10 | F8: Toast 'Coupon Removed'; DISCOUNT = 0; ô nhập mở lại | G8: Đúng như mong đợi | H8: Pass | I8: Major | J8: Selenium
A9: CPN-08 | B9: Áp hai mã liên tiếp | C9: Đã áp family10 | D9: 1. Thử nhập thêm mã khác khi đã áp mã | E9: family10 rồi family30 | F9: Không cộng dồn mã; ô nhập bị khóa cho đến khi gỡ mã | G9: Đúng như mong đợi | H9: Pass | I9: Major | J9: Selenium
A10: CPN-09 | B10: Mã bị reset khi rời và quay lại checkout | C10: Đã áp family10 | D10: 1. Bấm 'BACK TO CART' 2. Vào lại /checkout | E10: — | F10: DISCOUNT = 0; ô nhập trống | H10: Not Run | I10: Minor | J10: Selenium

Sheet TC_Checkout
A1: ID | B1: Mô tả | C1: Điều kiện tiên quyết | D1: Các bước thực hiện | E1: Dữ liệu test | F1: Kết quả mong đợi | G1: Kết quả thực tế | H1: Trạng thái | I1: Mức độ nếu lỗi | J1: Công cụ | K1: Ghi chú / Bug ID
A2: CO-01 | B2: Truy cập /checkout khi chưa đăng nhập | C2: Chưa đăng nhập | D2: 1. Mở /checkout | E2: — | F2: Chuyển sang /login | G2: Đúng như mong đợi | H2: Pass | I2: Major | J2: Selenium
A3: CO-02 | B3: Vào /checkout khi giỏ hàng trống | C3: Đã đăng nhập, giỏ trống | D3: 1. Mở /checkout 2. Điền form hợp lệ, đặt hàng | E3: — | F3: Bị chặn hoặc chuyển về /cart; không cho thanh toán 0 đồng | H3: Not Run | I3: Major | J3: Manual | K3: Gợi ý: liên quan BUG-15 (nghi vấn)
A4: CO-03 | B4: Order Summary khớp với giỏ hàng | C4: Đã đăng nhập; giỏ: 2 × Air Runner M (id=1) + 1 × Court Classic M (id=2) | D4: 1. Mở /checkout 2. Đọc ORDER SUMMARY | E4: 2 × Air Runner M (id=1) + 1 × Court Classic M (id=2) | F4: ITEMS: 2; QUANTITY: 3; ORIGINAL PRICE 2.248.000 ₫; TOTAL 1.798.000 ₫ | G4: Đúng như mong đợi | H4: Pass | I4: Critical | J4: Selenium
A5: CO-04 | B5: Để trống tất cả trường | C5: Đang ở /checkout có giỏ | D5: 1. Bấm nút đặt hàng khi form trống | E5: (trống) | F5: Toast 'Please fill the mandatory details' | G5: Đúng như mong đợi | H5: Pass | I5: Major | J5: Selenium
A6: CO-05 | B6: Để trống một trường bắt buộc | C6: Như CO-04 | D6: 1. Điền đủ trừ Town/City 2. Bấm đặt hàng | E6: Bỏ trống Town/City | F6: Toast 'Please fill the mandatory details' | G6: Đúng như mong đợi | H6: Pass | I6: Major | J6: Selenium
A7: CO-06 | B7: First/Last Name viết thường | C7: Như CO-04 | D7: 1. Điền form, First Name viết thường 2. Bấm đặt hàng 3. Lặp với Last Name | E7: First Name: an Last Name: nguyen | F7: Toast: First latter should be Capital in "an" (tương tự cho Last Name) | H7: Not Run | I7: Minor | J7: Selenium
A8: CO-07 | B8: Email sai định dạng | C8: Như CO-04 | D8: 1. Điền form với email sai 2. Bấm đặt hàng | E8: Email: an@example | F8: Toast 'Please provide a valid email id' | H8: Not Run | I8: Major | J8: Selenium
A9: CO-08 | B9: Pin Code không đủ 6 ký tự | C9: Như CO-04 | D9: 1. Nhập Pin Code 5 số 2. Bấm đặt hàng | E9: Pin Code: 12345 | F9: Toast 'Please provide 6 digit valid pincode' | H9: Not Run | I9: Major | J9: Selenium
A10: CO-09 | B10: Pin Code chứa chữ cái (đủ 6 ký tự) | C10: Như CO-04 | D10: 1. Nhập Pin Code có chữ 2. Bấm đặt hàng | E10: Pin Code: 12ab56 | F10: Báo lỗi: chỉ chấp nhận chữ số | G10: Đúng như mong đợi | H10: Pass | I10: Minor | J10: Selenium | K10: Bug: BUG-14 (không tái hiện qua UI)
A11: CO-10 | B11: Mobile không đủ 10 chữ số | C11: Như CO-04 | D11: 1. Nhập Mobile 9 số 2. Bấm đặt hàng | E11: Mobile: 091234567 | F11: Toast 'Please provide 10 digit valid mobile number' | H11: Not Run | I11: Major | J11: Selenium
A12: CO-11 | B12: Dữ liệu hợp lệ mở popup Razorpay | C12: Như CO-04; có Internet | D12: 1. Điền form hợp lệ (bỏ trống Address Line 2) 2. Bấm đặt hàng | E12: First: An; Last: Nguyen; Address 1: 12 Le Loi; Town: Bac Giang; Pin: 220000; State: Bac Ninh; Country: Vietnam; Email: an@example.com; Mobile: 0912345678 | F12: Popup Razorpay mở, tên cửa hàng 'Sports-K' | H12: Not Run | I12: Critical | J12: Selenium
A13: CO-12 | B13: Số tiền trong popup khớp tổng hiển thị | C13: Popup đã mở (CO-11), giỏ scenario CO-03 | D13: 1. So sánh số tiền trong popup với TOTAL trên trang | E13: TOTAL hiển thị: 1.798.000 ₫ | F13: Số tiền trong popup tương ứng cùng giá trị/đơn vị (code đang truyền 5992 × 100 với currency INR) | H13: Not Run | I13: Major | J13: Manual | K13: Gợi ý: liên quan BUG-06 (nghi vấn)
A14: CO-13 | B14: Thông tin prefill trong popup | C14: Popup đã mở (CO-11) | D14: 1. Xem các trường Name, Email, Contact trong popup | E14: An Nguyen / an@example.com / 0912345678 | F14: Name = 'An Nguyen'; Email và Contact đúng | H14: Not Run | I14: Minor | J14: Manual | K14: Gợi ý: liên quan BUG-07 (nghi vấn)
A15: CO-14 | B15: Thanh toán thành công bằng thẻ test | C15: Popup đã mở; key test còn hiệu lực | D15: 1. Nhập thẻ test theo tài liệu Razorpay 2. Hoàn tất thanh toán 3. Chọn 'Yes' trong hộp thoại | E15: Thẻ test Razorpay (xem tài liệu Razorpay) | F15: Hộp thoại 'Payment Success!'; hiển thị Payment ID; giỏ hàng bị xóa; chuyển về '/' | H15: Not Run | I15: Critical | J15: Manual
A16: CO-15 | B16: Đóng popup khi chưa thanh toán | C16: Popup đã mở | D16: 1. Đóng popup | E16: — | F16: Giỏ hàng giữ nguyên; ở lại /checkout | H16: Not Run | I16: Major | J16: Manual
A17: CO-16 | B17: Không tải được Razorpay SDK | C17: Chặn domain checkout.razorpay.com hoặc tắt mạng | D17: 1. Điền form hợp lệ 2. Bấm đặt hàng | E17: — | F17: Hiển thị thông báo 'Razorpay SDK failed to load. Are you online?'; không crash | H17: Not Run | I17: Minor | J17: Manual
A18: CO-17 | B18: Đơn hàng được lưu sau thanh toán | C18: Đã thanh toán thành công (CO-14) | D18: 1. Kiểm tra db.json và API xem có đơn hàng | E18: — | F18: Có bản ghi đơn hàng của người dùng | H18: Not Run | I18: Major | J18: Manual | K18: Gợi ý: liên quan BUG-10 (nghi vấn)
A19: CO-18 | B19: Nút BACK TO CART | C19: Đang ở /checkout | D19: 1. Bấm 'BACK TO CART' | E19: — | F19: Chuyển về /cart, giỏ hàng giữ nguyên | G19: Đúng như mong đợi | H19: Pass | I19: Trivial | J19: Selenium

Sheet TC_Admin
A1: ID | B1: Mô tả | C1: Điều kiện tiên quyết | D1: Các bước thực hiện | E1: Dữ liệu test | F1: Kết quả mong đợi | G1: Kết quả thực tế | H1: Trạng thái | I1: Mức độ nếu lỗi | J1: Công cụ | K1: Ghi chú / Bug ID
A2: ADM-01 | B2: Truy cập /admin khi chưa đăng nhập | C2: Chưa đăng nhập | D2: 1. Mở /admin | E2: — | F2: Chuyển sang /login | G2: Đúng như mong đợi | H2: Pass | I2: Major | J2: Selenium
A3: ADM-02 | B3: Người dùng thường truy cập /admin | C3: Đăng nhập test@example.com | D3: 1. Mở /admin | E3: test@example.com / 123456 | F3: Bị chặn hoặc chuyển hướng (chỉ admin được vào) | G3: AssertionError: User thường vào được /admin (nghi vấn BUG-04) | H3: Fail | I3: Critical | J3: Selenium | K3: Bug: BUG-04
A4: ADM-03 | B4: Danh sách sản phẩm trong trang Admin | C4: Vào được /admin | D4: 1. Quan sát danh sách | E4: — | F4: Hiển thị 28 sản phẩm gồm ảnh, tên, giới tính, loại, giá VND | G4: Đúng như mong đợi | H4: Pass | I4: Major | J4: Selenium
A5: ADM-04 | B5: Sửa tên sản phẩm | C5: Đã sao lưu db.json | D5: 1. Bấm nút sửa của id=1 2. Đổi Name 3. Lưu 4. Mở /allproducts | E5: Name: Air Runner M EDIT | F5: Danh sách Admin cập nhật; PATCH /allproducts/1 thành công; trang khách thấy tên mới | G5: Đúng như mong đợi | H5: Pass | I5: Major | J5: Selenium
A6: ADM-05 | B6: Sửa giá sản phẩm | C6: Đã sao lưu db.json | D6: 1. Sửa id=1, ô 'Price (VND)' 2. Lưu 3. Xem Admin và trang chi tiết | E6: Price: 500000 | F6: Hiển thị 500.000 ₫ nhất quán ở Admin và trang khách | H6: Not Run | I6: Major | J6: Selenium
A7: ADM-06 | B7: Nhập giá không hợp lệ | C7: Đang ở modal sửa | D7: 1. Nhập giá không hợp lệ 2. Lưu | E7: -1000, abc, (trống) | F7: Không cho lưu; báo lỗi rõ ràng | H7: Not Run | I7: Major | J7: Selenium
A8: ADM-07 | B8: Giá bán cao hơn giá gốc | C8: Đã sao lưu db.json | D8: 1. Sửa id=1, Price = 5000000 2. Xem trang chi tiết | E8: Giá gốc hiện tại: 712.000 ₫ | F8: Có cảnh báo/ràng buộc, hoặc giá gốc được cập nhật tương ứng | H8: Not Run | I8: Minor | J8: Manual | K8: Gợi ý: liên quan BUG-18 (nghi vấn)
A9: ADM-08 | B9: Xóa sản phẩm | C9: Dùng sản phẩm cuối danh sách; đã sao lưu db.json | D9: 1. Bấm biểu tượng thùng rác 2. Kiểm tra danh sách 3. GET /allproducts/{id} | E9: id = 28 | F9: Có xác nhận trước khi xóa; sản phẩm biến mất khỏi Admin và trang khách; API trả 404 | H9: Not Run | I9: Major | J9: Manual
A10: ADM-09 | B10: Chức năng thêm sản phẩm mới | C10: Vào được /admin | D10: 1. Tìm nút/chức năng thêm sản phẩm | E10: — | F10: Có thêm sản phẩm (hoàn chỉnh CRUD) | H10: Not Run | I10: Minor | J10: Manual
A11: ADM-10 | B11: Đăng xuất khỏi Admin | C11: Đang ở /admin | D11: 1. Mở menu Admin 2. Chọn Logout | E11: — | F11: Chuyển về /login; xóa token và userInfo | H11: Not Run | I11: Minor | J11: Selenium

Sheet TC_GiaoDien
A1: ID | B1: Mô tả | C1: Điều kiện tiên quyết | D1: Các bước thực hiện | E1: Dữ liệu test | F1: Kết quả mong đợi | G1: Kết quả thực tế | H1: Trạng thái | I1: Mức độ nếu lỗi | J1: Công cụ | K1: Ghi chú / Bug ID
A2: UI-01 | B2: Responsive trên desktop 1920×1080 | C2: — | D2: 1. Đặt kích thước cửa sổ 2. Duyệt Home, /allproducts, /cart | E2: 1920×1080 | F2: Bố cục đúng, không tràn ngang, không chồng lấn | G2: AssertionError: Có cuộn ngang ở 1920×1080 | H2: Fail | I2: Minor | J2: Selenium | K2: Ảnh: results/screenshots/UI-01.png; Bug: BUG-27
A3: UI-02 | B3: Responsive trên tablet 768×1024 | C3: — | D3: 1. Dùng DevTools, đặt kích thước 2. Duyệt các trang chính | E3: 768×1024 | F3: Bố cục thích ứng; các nút bấm được | G3: Đúng như mong đợi | H3: Pass | I3: Minor | J3: Manual
A4: UI-03 | B4: Responsive và điều hướng trên mobile 375×667 | C4: — | D4: 1. Dùng DevTools, đặt kích thước 2. Thử điều hướng tới Home / All / Men / Women / Shoes | E4: 375×667 | F4: Không cuộn ngang; vẫn điều hướng được (menu/sidebar) | G4: Đúng như mong đợi | H4: Pass | I4: Major | J4: Manual
A5: UI-04 | B5: Dark mode trên các trang chính | C5: — | D5: 1. Bật dark mode 2. Mở Home, /allproducts, /login, /register, /cart, /checkout | E5: Light ↔ Dark | F5: Toàn bộ trang đổi theme; chữ đọc được, tương phản đủ | H5: Not Run | I5: Minor | J5: Manual
A6: UI-05 | B6: Trang chủ: Carousel và khu vực sản phẩm | C6: — | D6: 1. Mở '/' 2. Quan sát Carousel và danh sách sản phẩm nổi bật | E6: — | F6: Carousel chuyển/điều hướng được; hiển thị 8 sản phẩm từ /Homepage | H6: Not Run | I6: Minor | J6: Selenium
A7: UI-06 | B7: Điều hướng Navbar và Footer | C7: — | D7: 1. Bấm lần lượt các liên kết trên Navbar, logo, Footer | E7: — | F7: Mỗi liên kết đưa tới đúng route (/, /allproducts, /men, /women, /shoes); không liên kết chết | G7: Đúng như mong đợi | H7: Pass | I7: Major | J7: Selenium
A8: UI-07 | B8: Ảnh sản phẩm không bị vỡ | C8: — | D8: 1. Duyệt các trang danh sách, chi tiết, giỏ, wishlist, admin 2. Kiểm tra naturalWidth của ảnh | E8: — | F8: Tất cả ảnh tải được | G8: Đúng như mong đợi | H8: Pass | I8: Minor | J8: Selenium
A9: UI-08 | B9: Tương thích trình duyệt | C9: — | D9: 1. Chạy luồng đăng nhập → thêm giỏ → mở checkout trên Chrome, Firefox, Edge | E9: Chrome, Firefox, Edge | F9: Kết quả giống nhau trên cả 3 trình duyệt | H9: Not Run | I9: Major | J9: Manual
A10: UI-09 | B10: Dừng mock-server khi đang dùng web | C10: Web đang chạy | D10: 1. Tắt mock-server (cổng 3001) 2. Mở /allproducts | E10: — | F10: Hiển thị thông báo lỗi thân thiện; không crash hoặc quay vô hạn | H10: Not Run | I10: Minor | J10: Manual
A11: UI-10 | B11: Truy cập URL không tồn tại | C11: — | D11: 1. Mở /abc | E11: URL: /abc | F11: Hiển thị trang 404 thân thiện hoặc chuyển về trang chủ | G11: AssertionError: Trang trắng khi vào URL không tồn tại (nghi vấn BUG-11) | H11: Fail | I11: Minor | J11: Selenium | K11: Bug: BUG-11
A12: UI-11 | B12: Hiệu năng tải trang (Lighthouse) | C12: Chạy bản build production | D12: 1. Chạy Lighthouse (Chrome DevTools) cho '/' và /allproducts | E12: Chrome, chế độ Mobile | F12: Performance ≥ 70; LCP < 2.5s (ghi nhận ảnh lớn như men.jpg ~3.9 MB) | H12: Not Run | I12: Minor | J12: Manual

Sheet TC_API
A1: ID | B1: Endpoint | C1: Method | D1: Mô tả | E1: Header / Tham số | F1: Body (JSON) | G1: Status mong đợi | H1: Kiểm tra (assertion) | I1: Kết quả thực tế | J1: Trạng thái | K1: Mức độ nếu lỗi | L1: Ghi chú / Bug ID
A2: API-01 | B2: /allproducts | C2: GET | D2: Lấy toàn bộ sản phẩm | E2: — | F2: — | G2: 200 | H2: Mảng 28 phần tử; có id, name, category, gender, colortype, sizes, rating, final_price, strike_price, images; Content-Type JSON; thời gian < 500 ms | I2: Status 200 Là mảng 28 phần tử Mỗi sản phẩm có đủ trường bắt buộc Content-Type là JSON Thời gian phản hồi < 500 ms | J2: Pass | K2: Major
A3: API-02 | B3: /allproducts?category=shoes | C3: GET | D3: Lọc theo loại giày | E3: category=shoes | F3: — | G3: 200 | H3: 16 phần tử; tất cả category = shoes | I3: Status 200 Là mảng 16 phần tử Tất cả category = shoes Thời gian phản hồi < 500 ms | J3: Pass | K3: Major
A4: API-03 | B4: /allproducts?gender=MEN | C4: GET | D4: Lọc theo giới tính | E4: gender=MEN | F4: — | G4: 200 | H4: 14 phần tử; tất cả gender = MEN | I4: Status 200 Là mảng 14 phần tử Tất cả gender = MEN Thời gian phản hồi < 500 ms | J4: Pass | K4: Major
A5: API-04 | B5: /allproducts?colortype=black | C5: GET | D5: Lọc theo một màu | E5: colortype=black | F5: — | G5: 200 | H5: 7 phần tử; tất cả colortype = black | I5: Status 200 Là mảng 7 phần tử Tất cả colortype = black Thời gian phản hồi < 500 ms | J5: Pass | K5: Major
A6: API-05 | B6: /allproducts?colortype=red&colortype=blue | C6: GET | D6: Lọc nhiều màu | E6: colortype=red&colortype=blue | F6: — | G6: 200 | H6: 14 phần tử; colortype thuộc {red, blue} | I6: Status 200 Là mảng 14 phần tử colortype thuộc {red, blue} Thời gian phản hồi < 500 ms | J6: Pass | K6: Major
A7: API-06 | B7: /allproducts?category=shoes&gender=WOMEN&colortype=white | C7: GET | D7: Kết hợp 3 bộ lọc | E7: category, gender, colortype | F7: — | G7: 200 | H7: 2 phần tử khớp cả 3 điều kiện | I7: Status 200 Là mảng 2 phần tử Khớp cả 3 điều kiện Thời gian phản hồi < 500 ms | J7: Pass | K7: Major
A8: API-07 | B8: /allproducts?sizes=small | C8: GET | D8: Lọc theo size (trường mảng) | E8: sizes=small | F8: — | G8: 200 | H8: 12 phần tử; mỗi phần tử có 'small' trong sizes | I8: Status 200 Là mảng 12 phần tử Mỗi sản phẩm có size small Thời gian phản hồi < 500 ms | J8: Pass | K8: Major
A9: API-08 | B9: /allproducts?_sort=rating&_order=desc | C9: GET | D9: Sắp xếp rating giảm dần | E9: _sort=rating&_order=desc | F9: — | G9: 200 | H9: Mảng có rating không tăng; số phần tử không đổi | I9: Status 200 Là mảng 28 phần tử Rating giảm dần Thời gian phản hồi < 500 ms | J9: Pass | K9: Major
A10: API-09 | B10: /allproducts?category=xyz | C10: GET | D10: Giá trị lọc không tồn tại | E10: category=xyz | F10: — | G10: 200 | H10: Mảng rỗng []; không lỗi 500 | I10: Status 200 Trả mảng rỗng Thời gian phản hồi < 500 ms | J10: Pass | K10: Minor
A11: API-10 | B11: /allproducts/1 | C11: GET | D11: Lấy 1 sản phẩm theo id | E11: — | F11: — | G11: 200 | H11: name = 'Air Runner M'; final_price = 1873 | I11: Status 200 name = Air Runner M final_price = 1873 Thời gian phản hồi < 500 ms | J11: Pass | K11: Major
A12: API-11 | B12: /allproducts/9999 | C12: GET | D12: Sản phẩm không tồn tại | E12: — | F12: — | G12: 404 | H12: Trả 404; không lỗi 500 | I12: Status 404 | J12: Pass | K12: Minor
A13: API-12 | B13: /Homepage | C13: GET | D13: Danh sách sản phẩm trang chủ | E13: — | F13: — | G13: 200 | H13: Mảng 8 phần tử | I13: Status 200 Là mảng 8 phần tử Thời gian phản hồi < 500 ms | J13: Pass | K13: Minor
... A23: API-22 | B23: /auth/login | C23: POST | D23: Email là object (injection kiểu NoSQL) | E23: Content-Type: application/json | F23: {"email":{"$ne":null},"password":"x"} | G23: 401 | H23: Không đăng nhập được; server không crash (không 500) | I23: Không đăng nhập được, không lỗi 500 | J23: Pass | K23: Major
A24: API-23 | B24: /auth/test@example.com | C24: GET | D24: Lấy hồ sơ không kèm Authorization | E24: (không có header Authorization) | F24: — | G24: 401 | H24: Server yêu cầu xác thực | I24: [BUG-03] Yêu cầu xác thực → 401 | AssertionError: expected 200 to deeply equal 401 | J24: Fail | K24: Critical | L24: Gợi ý: liên quan BUG-03 (nghi vấn)
A25: API-24 | B25: /auth/test@example.com | C25: GET | D25: Lấy hồ sơ kèm token hợp lệ | E25: Authorization: Bearer {token từ API-18} | F25: — | G25: 200 | H25: Có name, email, mobile; KHÔNG có trường password | I25: Status 200 Có name, email, mobile Không có trường password | J25: Pass | K25: Major
A26: API-25 | B26: /users | C26: GET | D26: Kiểm tra lộ danh sách người dùng | E26: (không header) | F26: — | G26: 401/403/404 | H26: Không trả danh sách người dùng; không lộ password | I26: [BUG-02] Không lộ danh sách người dùng (401/403/404) | AssertionError: expected [ 401, 403, 404 ] to include 200 [BUG-02] Không có trường password trong phản hồi | AssertionError: expected true to deeply equal false | J26: Fail | K26: Critical | L26: Gợi ý: liên quan BUG-02 (nghi vấn)
A27: API-26 | B27: /allproducts | C27: POST | D27: Tạo sản phẩm khi không xác thực | E27: Content-Type: application/json | F27: {"name":"Test Product","category":"shoes","gender":"MEN","final_price":1000,"strike_price":1500,"sizes":["8"],"images":[]} | G27: 401/403 | H27: Server từ chối (dùng bản ghi test, xóa sau khi kiểm tra) | I27: [BUG-05] Server từ chối tạo sản phẩm khi chưa xác thực (401/403) | AssertionError: expected [ 401, 403 ] to in | J27: Fail | K27: Critical | L27: Gợi ý: liên quan BUG-05 (nghi vấn)
A28: API-27 | B28: /allproducts/{id_test} | C28: PATCH | D28: Sửa sản phẩm khi không xác thực | E28: Content-Type: application/json | F28: {"name":"Hacked"} | G28: 401/403 | H28: Server từ chối (chỉ thao tác trên bản ghi test) | I28: [BUG-05] Server từ chối sửa khi chưa xác thực (401/403) | AssertionError: expected [ 401, 403 ] to include 200 | J28: Fail | K28: Critical | L28: Gợi ý: liên quan BUG-05 (nghi vấn)
A29: API-28 | B29: /allproducts/{id_test} | C29: DELETE | D29: Xóa sản phẩm khi không xác thực | E29: (không header) | F29: — | G29: 401/403 | H29: Server từ chối (chỉ thao tác trên bản ghi test) | I29: [BUG-05] Server từ chối xóa khi chưa xác thực (401/403) | AssertionError: expected [ 401, 403 ] to include 20 | J29: Fail | K29: Critical | L29: Gợi ý: liên quan BUG-05 (nghi vấn)
A30: API-29 | B30: /auth/login | C30: POST | D30: Kiểm tra định dạng token | E30: Content-Type: application/json | F30: {"email":"test@example.com","password":"123456"} | G30: 200 | H30: Token không giải mã Base64 ra 'email:timestamp'; có chữ ký/thời hạn (ví dụ JWT) | I30: [BUG-17] Token không phải Base64 của 'email:timestamp' | AssertionError: expected 'test@example.com:179256 | J30: Fail | K30: Major | L30: Gợi ý: liên quan BUG-17 (nghi vấn)
A31: API-30 | B31: /photos/giay1.jpg | C31: GET | D31: Tải ảnh tĩnh | E31: — | F31: — | G31: 200 | H31: Content-Type image/jpeg; kích thước > 0 | I31: Status 200 Content-Type là ảnh jpeg Kích thước > 0 | J31: Pass | K31: Minor

Sheet Bug_Report
A1: Bug ID | B1: Test Case ID | C1: Module | D1: Tiêu đề | E1: Các bước tái hiện | F1: Kết quả mong đợi | G1: Kết quả thực tế | H1: Mức độ | I1: Độ ưu tiên | J1: Trạng thái | K1: File mã nguồn liên quan | L1: Bằng chứng (ảnh/log) | M1: Ngày phát hiện | N1: Người ghi nhận
A2: BUG-01 | B2: REG-09 | C2: Đăng ký | D2: Mật khẩu không có chữ hoa vẫn được chấp nhận | E2: 1. Mở /register 2. Nhập mật khẩu 'abc#1234' cùng các trường hợp lệ khác 3. Bấm Sign up | F2: Báo lỗi 'at least one upper case', không cho đăng ký | G2: Không có thông báo lỗi chữ hoa; mật khẩu 'abc#1234' vượt qua bước kiểm tra mật khẩu (Selenium REG-09 Fail). Điều kiện kiểm tra chữ thường cũng lỗi tương tự (/[a-z]/i): 'ABC#1234' không bị báo thiếu chữ thường. | H2: Major | I2: High | J2: Đã xác nhận | K2: src/components/Other/CheckProperty.jsx (checkPassword: regex /[A-Z]/i có cờ i nên khớp cả chữ thường) | L2: Unit test CheckProperty.test.js: checkPassword('abc#1234') trả status = true (Pass) – log Jest Selenium: results/screenshots/REG-09.png | M2: 28/10/2026
A3: BUG-02 | B3: API-25 | C3: API / Bảo mật | D3: GET /users trả về toàn bộ người dùng kèm mật khẩu dạng plaintext | E3: 1. Gửi GET http://localhost:3001/users (không header) 2. Xem body | F3: 401/403/404; không bao giờ lộ mật khẩu | G3: GET /users trả 200 kèm danh sách user và mật khẩu plaintext | H3: Critical | I3: High | J3: Đã xác nhận | K3: mock-server/server.js (server.use(router) mở mọi collection); db.json lưu password plaintext
A4: BUG-03 | B4: API-23 | C4: API / Bảo mật | D4: GET /auth/:email không kiểm tra Authorization | E4: 1. Gửi GET /auth/test@example.com không kèm header Authorization | F4: 401 Unauthorized | G4: GET /auth/test@example.com trả 200 khi không có Authorization | H4: Critical | I4: High | J4: Đã xác nhận | K4: mock-server/server.js (route /auth/:email không đọc token)
A5: BUG-04 | B5: ADM-02 | C5: Admin / Phân quyền | D5: Người dùng thường truy cập được trang /admin | E5: 1. Đăng nhập test@example.com / 123456 2. Mở trực tiếp /admin | F5: Bị chặn / chuyển hướng (chỉ admin được vào) | G5: Vẫn ở lại http://localhost:3000/admin và thấy danh sách 28 sản phẩm cùng nút sửa/xóa (Selenium ADM-02 Fail). Route chỉ kiểm tra đã đăng nhập, không kiểm tra vai trò. | H5: Critical | I5: High | J5: Đã xác nhận | K5: src/AllRoutes/AllRoutes.jsx; src/PrivateRoute/Authentication.jsx (chỉ kiểm tra isAuth, không có vai trò) | L5: results/screenshots/ADM-02.png | M5: 28/10/2026
A6: BUG-05 | B6: API-26, API-27, API-28 | C6: API / Bảo mật | D6: Thêm / sửa / xóa sản phẩm qua API không cần xác thực | E6: 1. POST /allproducts với body sản phẩm test 2. PATCH /allproducts/{id} đổi tên 3. DELETE /allproducts/{id} (chỉ thao tác trên bản ghi test vừa tạo) | F6: 401/403 khi không có token quản trị | G6: POST, PATCH, DELETE /allproducts đều thành công khi không có token | H6: Critical | I6: High | J6: Đã xác nhận | K6: mock-server/server.js (json-server router không có middleware xác thực)
A7: BUG-06 | B7: CO-12 | C7: Checkout / Thanh toán | D7: Số tiền trong popup Razorpay lệch đơn vị so với giá hiển thị (VND) | E7: 1. Thêm sản phẩm vào giỏ, vào /checkout 2. Điền form hợp lệ, bấm đặt hàng 3. So sánh số tiền trong popup với TOTAL trên trang | F7: Số tiền thanh toán khớp TOTAL hiển thị (cùng đơn vị tiền) | G7: (Điền sau khi tái hiện) | H7: Major | I7: High | J7: Nghi vấn - cần xác minh | K7: src/Pages/Checkout.jsx (truyền total_discount tính theo INR gốc); src/components/rozarpay/RozarPay.jsx (amount*100, currency INR)
A8: BUG-07 | B8: CO-13 | C8: Checkout / Thanh toán | D8: Popup Razorpay prefill tên sai (undefined undefined) | E8: 1. Điền First Name 'An', Last Name 'Nguyen' 2. Mở popup Razorpay, xem trường tên | F8: Tên hiển thị 'An Nguyen' | G8: (Điền sau khi tái hiện) | H8: Minor | I8: Medium | J8: Nghi vấn - cần xác minh | K8: src/components/rozarpay/RozarPay.jsx (destructure firstname/lastname trong khi form dùng firstName/lastName)
A9: BUG-08 | B9: LOG-10 | C9: Bảo mật mã nguồn | D9: Tài khoản admin và key Razorpay bị hardcode trong mã nguồn | E9: 1. Mở Login.jsx và RozarPay.jsx 2. Tìm email/mật khẩu admin và key rzp_test_... | F9: Thông tin nhạy cảm nằm trong biến môi trường / backend, không nằm trong source | G9: (Điền sau khi tái hiện) | H9: Major | I9: High | J9: Nghi vấn - cần xác minh | K9: src/Pages/Login.jsx; src/components/rozarpay/RozarPay.jsx (SonarQube: security hotspot / vulnerability) | L9: SonarQube: Security issues = 0, không phát hiện. Phát hiện bằng đọc mã: Login.jsx L41, RozarPay.jsx L34
A10: BUG-09 | B10: CART-09, WL-06 | C10: Giỏ hàng | D10: Giỏ hàng và danh sách yêu thích bị mất khi tải lại trang | E10: 1. Thêm sản phẩm vào giỏ và vào danh sách yêu thích (cần đăng nhập) 2. Nhấn F5 ở /cart 3. Nhấn F5 ở /wishlist | F10: Giỏ hàng và wishlist vẫn giữ nguyên sau khi tải lại | G10: Giỏ hàng rỗng sau F5 (CART-09: 0 dòng thay vì 1); wishlist không còn sản phẩm (WL-06 Fail). Hai trạng thái chỉ nằm trong Redux, không lưu localStorage hay API. | H10: Major | I10: Medium | J10: Đã xác nhận | K10: src/redux/store.js; src/redux/CartReducer/reducer.js; src/redux/WishReducer (không persist) | L10: results/screenshots/CART-09.png; results/screenshots/WL-06.png | M10: 28/10/2026
A11: BUG-10 | B11: CO-17 | C11: Checkout / Đặt hàng | D11: Đơn hàng không được lưu sau khi thanh toán | E11: 1. Thanh toán thành công bằng thẻ test 2. Kiểm tra db.json / API | F11: Có bản ghi đơn hàng (và lịch sử đơn của người dùng) | G11: (Điền sau khi tái hiện) | H11: Major | I11: Medium | J11: Nghi vấn - cần xác minh | K11: src/components/rozarpay/RozarPay.jsx; mock-server/server.js (không có collection orders)
A12: BUG-11 | B12: UI-10 | C12: Giao diện | D12: Truy cập URL không tồn tại hiển thị trang trắng | E12: 1. Mở http://localhost:3000/abc | F12: Trang 404 thân thiện hoặc chuyển về trang chủ | G12: Phần thân trang trắng hoàn toàn, chỉ hiển thị footer; không có trang 404 và không chuyển hướng (Selenium UI-10 Fail, đã xác nhận thủ công). | H12: Minor | I12: Low | J12: Đã xác nhận | K12: src/AllRoutes/AllRoutes.jsx (không có route path='*') | L12: results/screenshots/UI-10.png | M12: 28/10/2026
A13: BUG-12 | B13: LOG-04 | C13: Đăng nhập | D13: Bấm Sign in khi để trống không có phản hồi nào | E13: 1. Mở /login, để trống Email hoặc Password 2. Bấm Sign in | F13: Hiển thị thông báo yêu cầu nhập đủ thông tin | G13: Không có toast hay thông báo nào; form không phản hồi (Selenium LOG-04 Fail). loginHandler chỉ có nhánh admin và nhánh 'email && password', không có else. | H13: Minor | I13: Low | J13: Đã xác nhận | K13: src/Pages/Login.jsx (loginHandler không có nhánh else) | L13: results/screenshots/LOG-04.png | M13: 28/10/2026
A14: BUG-13 | B14: LOG-02 | C14: Đăng nhập | D14: Đăng nhập sai có thể hiện thêm toast rỗng / trùng | E14: 1. Đăng nhập với mật khẩu sai 2. Đếm số toast xuất hiện | F14: Chỉ 1 toast 'Wrong email or password' | G14: Chỉ xuất hiện đúng 1 toast 'Wrong email or password' (Selenium LOG-02 Pass). Không tái hiện được lỗi toast trùng/rỗng. | H14: Minor | I14: Low | J14: Không phải lỗi | K14: src/redux/AuthReducer/action.js (catch trả về action lỗi); src/Pages/Login.jsx (đọc res.payload.msg) | L14: Selenium LOG-02: Pass | M14: 28/10/2026
A15: BUG-14 | B15: REG-12, CO-09 | C15: Validate dữ liệu | D15: Hàm kiểm tra SĐT / mã bưu điện chỉ kiểm tra độ dài (UI chặn chữ cái nhờ ô type=number) | E15: 1. Nhập SĐT '09123abcde' hoặc Pin Code '12ab56' 2. Gửi form | F15: Báo lỗi: chỉ chấp nhận chữ số | G15: Trên giao diện: gõ '09123abcde' hoặc '12ab56' đều bị chặn/báo lỗi vì ô type=number loại bỏ chữ cái (Selenium REG-12, CO-09 Pass). Hàm checkMobile/checkPinCode vẫn chỉ kiểm tra độ dài (Jest). Cần thử thủ công chuỗi hợp lệ dạng số mũ như '091234e567' để xem có lọt qua không. | H15: Minor | I15: Medium | J15: Nghi vấn - cần xác minh | K15: src/components/Other/CheckProperty.jsx (checkMobile, checkPinCode) | L15: Unit test CheckProperty.test.js: checkMobile('09123abcde') trả status = true (Pass) – log Jest Selenium: REG-12, CO-09 Pass | M15: 28/10/2026
A16: BUG-15 | B16: CO-02 | C16: Checkout | D16: Có thể thanh toán khi giỏ hàng trống | E16: 1. Đăng nhập, để giỏ trống 2. Mở /checkout, điền form hợp lệ, đặt hàng | F16: Bị chặn hoặc chuyển về /cart | G16: (Điền sau khi tái hiện) | H16: Major | I16: Medium | J16: Nghi vấn - cần xác minh | K16: src/Pages/Checkout.jsx (không kiểm tra cart.length)
